Workbook

Sheet VAT
A1: Country | B1: Country Code | C1: Year | D1: VAT Collection (% of GDP) | E1: GDP_LCU | F1: VAT Collection (LCU) | G1: C | H1: G | I1: VAT Rate
A2: Albania | B2: =VLOOKUP(A2,GDP_LCU!A:B,2,FALSE) -> ALB | C2: 2019 | D2: 0.078262004 | E2: =VLOOKUP(A2,GDP_LCU!A:C,3,FALSE) -> 1691903429800 | F2: =D2*E2 -> 1.3241175e+11 | G2: =IFERROR(VLOOKUP(B2,'C'!B:C,2,FALSE),"") -> 1353526016200 | H2: =IFERROR(VLOOKUP(B2,G!B:C,2,FALSE),"") -> 191980010300 | I2: =IFERROR(VLOOKUP(B2,'VAT Rates'!B:C,2,FALSE),"") -> 20
A3: Antigua and Barbuda | B3: =VLOOKUP(A3,GDP_LCU!A:B,2,FALSE) -> ATG | C3: 2019 | D3: 0.055432397 | E3: =VLOOKUP(A3,GDP_LCU!A:C,3,FALSE) -> 4.65845e+09 | F3: =D3*E3 -> 2.5822905e+08 | G3: =IFERROR(VLOOKUP(B3,'C'!B:C,2,FALSE),"") | H3: =IFERROR(VLOOKUP(B3,G!B:C,2,FALSE),"") | I3: =IFERROR(VLOOKUP(B3,'VAT Rates'!B:C,2,FALSE),"") -> 15
A4: Argentina | B4: =VLOOKUP(A4,GDP_LCU!A:B,2,FALSE) -> ARG | C4: 2019 | D4: 0.070295334 | E4: =VLOOKUP(A4,GDP_LCU!A:C,3,FALSE) -> 21558444149200 | F4: =D4*E4 -> 1.515458e+12 | G4: =IFERROR(VLOOKUP(B4,'C'!B:C,2,FALSE),"") -> 14256078760800 | H4: =IFERROR(VLOOKUP(B4,G!B:C,2,FALSE),"") -> 3544907053700 | I4: =IFERROR(VLOOKUP(B4,'VAT Rates'!B:C,2,FALSE),"") -> 21
A5: Armenia | B5: =VLOOKUP(A5,GDP_LCU!A:B,2,FALSE) -> ARM | C5: 2019 | D5: 0.072494585 | E5: =VLOOKUP(A5,GDP_LCU!A:C,3,FALSE) -> 6.5433218e+12 | F5: =D5*E5 -> 4.743554e+11 | G5: =IFERROR(VLOOKUP(B5,'C'!B:C,2,FALSE),"") -> 5.4597125e+12 | H5: =IFERROR(VLOOKUP(B5,G!B:C,2,FALSE),"") -> 822139600000 | I5: =IFERROR(VLOOKUP(B5,'VAT Rates'!B:C,2,FALSE),"") -> 20
A6: Aruba | B6: =VLOOKUP(A6,GDP_LCU!A:B,2,FALSE) -> ABW | C6: 2019 | D6: 0.035820896 | E6: =VLOOKUP(A6,GDP_LCU!A:C,3,FALSE) -> 6078480000 | F6: =D6*E6 -> 2.177366e+08 | G6: =IFERROR(VLOOKUP(B6,'C'!B:C,2,FALSE),"") -> 3278570000 | H6: =IFERROR(VLOOKUP(B6,G!B:C,2,FALSE),"") -> 1367570000 | I6: =IFERROR(VLOOKUP(B6,'VAT Rates'!B:C,2,FALSE),"")
A7: Australia | B7: =VLOOKUP(A7,GDP_LCU!A:B,2,FALSE) -> AUS | C7: 2019 | D7: 0.032153224 | E7: =VLOOKUP(A7,GDP_LCU!A:C,3,FALSE) -> 1950042000000 | F7: =D7*E7 -> 6.2700137e+10 | G7: =IFERROR(VLOOKUP(B7,'C'!B:C,2,FALSE),"") -> 1051491000000 | H7: =IFERROR(VLOOKUP(B7,G!B:C,2,FALSE),"") -> 396695000000 | I7: =IFERROR(VLOOKUP(B7,'VAT Rates'!B:C,2,FALSE),"") -> 10
A8: Austria | B8: =VLOOKUP(A8,GDP_LCU!A:B,2,FALSE) -> AUT | C8: 2019 | D8: 0.076605814 | E8: =VLOOKUP(A8,GDP_LCU!A:C,3,FALSE) -> 397147190000 | F8: =D8*E8 -> 3.0423784e+10 | G8: =IFERROR(VLOOKUP(B8,'C'!B:C,2,FALSE),"") -> 204754180000 | H8: =IFERROR(VLOOKUP(B8,G!B:C,2,FALSE),"") -> 77286760000 | I8: =IFERROR(VLOOKUP(B8,'VAT Rates'!B:C,2,FALSE),"") -> 20
A9: Azerbaijan | B9: =VLOOKUP(A9,GDP_LCU!A:B,2,FALSE) -> AZE | C9: 2019 | D9: 0.063313227 | E9: =VLOOKUP(A9,GDP_LCU!A:C,3,FALSE) -> 8.18962e+10 | F9: =D9*E9 -> 5.1851127e+09 | G9: =IFERROR(VLOOKUP(B9,'C'!B:C,2,FALSE),"") -> 4.70958e+10 | H9: =IFERROR(VLOOKUP(B9,G!B:C,2,FALSE),"") -> 9109700000 | I9: =IFERROR(VLOOKUP(B9,'VAT Rates'!B:C,2,FALSE),"")
A10: Bahamas, The | B10: =VLOOKUP(A10,GDP_LCU!A:B,2,FALSE) -> BHS | C10: 2019 | D10: 0.067958008 | E10: =VLOOKUP(A10,GDP_LCU!A:C,3,FALSE) -> 13016200000 | F10: =D10*E10 -> 8.8455502e+08 | G10: =IFERROR(VLOOKUP(B10,'C'!B:C,2,FALSE),"") -> 7.9768e+09 | H10: =IFERROR(VLOOKUP(B10,G!B:C,2,FALSE),"") -> 1636800000 | I10: =IFERROR(VLOOKUP(B10,'VAT Rates'!B:C,2,FALSE),"") -> 12
A11: Bahrain | B11: =VLOOKUP(A11,GDP_LCU!A:B,2,FALSE) -> BHR | C11: 2019 | D11: 0.017912403 | E11: =VLOOKUP(A11,GDP_LCU!A:C,3,FALSE) -> 14533647600 | F11: =D11*E11 -> 2.6033255e+08 | G11: =IFERROR(VLOOKUP(B11,'C'!B:C,2,FALSE),"") -> 5.8719e+09 | H11: =IFERROR(VLOOKUP(B11,G!B:C,2,FALSE),"") -> 2280320000 | I11: =IFERROR(VLOOKUP(B11,'VAT Rates'!B:C,2,FALSE),"") -> 5
A12: Barbados | B12: =VLOOKUP(A12,GDP_LCU!A:B,2,FALSE) -> BRB | C12: 2019 | D12: 0.091260853 | E12: =VLOOKUP(A12,GDP_LCU!A:C,3,FALSE) -> 10734278500 | F12: =D12*E12 -> 9.7961941e+08 | G12: =IFERROR(VLOOKUP(B12,'C'!B:C,2,FALSE),"") -> 7932154000 | H12: =IFERROR(VLOOKUP(B12,G!B:C,2,FALSE),"") -> 1161351200 | I12: =IFERROR(VLOOKUP(B12,'VAT Rates'!B:C,2,FALSE),"") -> 17.5
A13: Belarus | B13: =VLOOKUP(A13,GDP_LCU!A:B,2,FALSE) -> BLR | C13: 2019 | D13: 0.083566901 | E13: =VLOOKUP(A13,GDP_LCU!A:C,3,FALSE) -> 134732000000 | F13: =D13*E13 -> 1.1259136e+10 | G13: =IFERROR(VLOOKUP(B13,'C'!B:C,2,FALSE),"") -> 7.2706e+10 | H13: =IFERROR(VLOOKUP(B13,G!B:C,2,FALSE),"") -> 22693000000 | I13: =IFERROR(VLOOKUP(B13,'VAT Rates'!B:C,2,FALSE),"") -> 20
... A125: Zimbabwe | B125: =VLOOKUP(A125,GDP_LCU!A:B,2,FALSE) -> ZWE | C125: 2019 | D125: 0.02803844 | E125: =VLOOKUP(A125,GDP_LCU!A:C,3,FALSE) -> 212174391900 | F125: =D125*E125 -> 5.949039e+09 | G125: =IFERROR(VLOOKUP(B125,'C'!B:C,2,FALSE),"") -> 168782894500 | H125: =IFERROR(VLOOKUP(B125,G!B:C,2,FALSE),"") -> 15571819900 | I125: =IFERROR(VLOOKUP(B125,'VAT Rates'!B:C,2,FALSE),"") -> 15

Sheet GDP_LCU
A1: Country Name | B1: Country Code | C1: GDP_2019
A2: Aruba | B2: ABW | C2: 6078480000
A3: Africa Eastern and Southern | B3: AFE
A4: Afghanistan | B4: AFG | C4: 1.4695963e+12
A5: Africa Western and Central | B5: AFW
A6: Angola | B6: AGO | C6: 30330429000000
A7: Albania | B7: ALB | C7: 1691903429800
A8: Andorra | B8: AND | C8: 2.81842e+09
A9: Arab World | B9: ARB
A10: United Arab Emirates | B10: ARE | C10: 1.5350673e+12
A11: Argentina | B11: ARG | C11: 21558444149200
A12: Armenia | B12: ARM | C12: 6.5433218e+12
A13: American Samoa | B13: ASM | C13: 647000000
A14: Antigua and Barbuda | B14: ATG | C14: 4.65845e+09
A15: Australia | B15: AUS | C15: 1950042000000
A16: Austria | B16: AUT | C16: 397147190000
A17: Azerbaijan | B17: AZE | C17: 8.18962e+10
A18: Burundi | B18: BDI | C18: 5559586343900
A19: Belgium | B19: BEL | C19: 4.786762e+11
A20: Benin | B20: BEN | C20: 8.4322475e+12
A21: Burkina Faso | B21: BFA | C21: 9.393802e+12
... A37: Canada | B37: CAN | C37: 2313563000000
A38: Central Europe and the Baltics | B38: CEB
A39: Switzerland | B39: CHE | C39: 716878590000
A40: Channel Islands | B40: CHI | C40: 7.7724142e+09
A41: Chile | B41: CHL | C41: 195531722450800
A42: China, P.R.: Mainland | B42: CHN | C42: 98651520229200
A43: Cote d'Ivoire | B43: CIV | C43: 3.5379003e+13
A44: Cameroon | B44: CMR | C44: 23243662000000
A45: Congo, Dem. Rep. | B45: COD | C45: 85314148014000
A46: Congo, Rep. | B46: COG | C46: 8.1890657e+12
A47: Colombia | B47: COL | C47: 1.060068e+15
A48: Comoros | B48: COM | C48: 525167000000
A49: Cabo Verde | B49: CPV | C49: 2.2182859e+11
A50: Costa Rica | B50: CRI | C50: 37832149784000
A51: Caribbean small states | B51: CSS
A52: Cuba | B52: CUB | C52: 103427600000
A53: Curacao | B53: CUW | C53: 5416762200
A54: Cayman Islands | B54: CYM | C54: 4.9515607e+09
A55: Cyprus | B55: CYP | C55: 2.3177857e+10
...

Sheet C
A1: Country Name | B1: Country Code | C1: House_Cons_2019
A2: Aruba | B2: =VLOOKUP(A2,GDP_LCU!A:B,2,FALSE) -> ABW | C2: 3278570000
A3: Africa Eastern and Southern | B3: =VLOOKUP(A3,GDP_LCU!A:B,2,FALSE) -> AFE
A4: Afghanistan | B4: =VLOOKUP(A4,GDP_LCU!A:B,2,FALSE) -> AFG
A5: Africa Western and Central | B5: =VLOOKUP(A5,GDP_LCU!A:B,2,FALSE) -> AFW
A6: Angola | B6: =VLOOKUP(A6,GDP_LCU!A:B,2,FALSE) -> AGO | C6: 15146080000000
A7: Albania | B7: =VLOOKUP(A7,GDP_LCU!A:B,2,FALSE) -> ALB | C7: 1353526016200
A8: Andorra | B8: =VLOOKUP(A8,GDP_LCU!A:B,2,FALSE) -> AND
A9: Arab World | B9: =VLOOKUP(A9,GDP_LCU!A:B,2,FALSE) -> ARB
A10: United Arab Emirates | B10: =VLOOKUP(A10,GDP_LCU!A:B,2,FALSE) -> ARE | C10: 6.0162527e+11
A11: Argentina | B11: =VLOOKUP(A11,GDP_LCU!A:B,2,FALSE) -> ARG | C11: 14256078760800
A12: Armenia | B12: =VLOOKUP(A12,GDP_LCU!A:B,2,FALSE) -> ARM | C12: 5.4597125e+12
A13: American Samoa | B13: =VLOOKUP(A13,GDP_LCU!A:B,2,FALSE) -> ASM | C13: 509000000
A14: Antigua and Barbuda | B14: =VLOOKUP(A14,GDP_LCU!A:B,2,FALSE) -> ATG
A15: Australia | B15: =VLOOKUP(A15,GDP_LCU!A:B,2,FALSE) -> AUS | C15: 1051491000000
A16: Austria | B16: =VLOOKUP(A16,GDP_LCU!A:B,2,FALSE) -> AUT | C16: 204754180000
A17: Azerbaijan | B17: =VLOOKUP(A17,GDP_LCU!A:B,2,FALSE) -> AZE | C17: 4.70958e+10
A18: Burundi | B18: =VLOOKUP(A18,GDP_LCU!A:B,2,FALSE) -> BDI | C18: 4298041148100
A19: Belgium | B19: =VLOOKUP(A19,GDP_LCU!A:B,2,FALSE) -> BEL | C19: 245666800000
A20: Benin | B20: =VLOOKUP(A20,GDP_LCU!A:B,2,FALSE) -> BEN | C20: 5.7717397e+12
A21: Burkina Faso | B21: =VLOOKUP(A21,GDP_LCU!A:B,2,FALSE) -> BFA | C21: 5.789916e+12
A22: Bangladesh | B22: =VLOOKUP(A22,GDP_LCU!A:B,2,FALSE) -> BGD | C22: 19738395000000
A23: Bulgaria | B23: =VLOOKUP(A23,GDP_LCU!A:B,2,FALSE) -> BGR | C23: 7.1096588e+10
A24: Bahrain | B24: =VLOOKUP(A24,GDP_LCU!A:B,2,FALSE) -> BHR | C24: 5.8719e+09
A25: Bahamas, The | B25: =VLOOKUP(A25,GDP_LCU!A:B,2,FALSE) -> BHS | C25: 7.9768e+09
A26: Bosnia and Herzegovina | B26: =VLOOKUP(A26,GDP_LCU!A:B,2,FALSE) -> BIH | C26: 25886036000
... A37: Canada | B37: =VLOOKUP(A37,GDP_LCU!A:B,2,FALSE) -> CAN | C37: 1336188000000
A38: Central Europe and the Baltics | B38: =VLOOKUP(A38,GDP_LCU!A:B,2,FALSE) -> CEB
A39: Switzerland | B39: =VLOOKUP(A39,GDP_LCU!A:B,2,FALSE) -> CHE | C39: 375673974000
A40: Channel Islands | B40: =VLOOKUP(A40,GDP_LCU!A:B,2,FALSE) -> CHI
A41: Chile | B41: =VLOOKUP(A41,GDP_LCU!A:B,2,FALSE) -> CHL | C41: 120583344531700
A42: China, P.R.: Mainland | B42: =VLOOKUP(A42,GDP_LCU!A:B,2,FALSE) -> CHN | C42: 38718809952500
A43: Cote d'Ivoire | B43: =VLOOKUP(A43,GDP_LCU!A:B,2,FALSE) -> CIV | C43: 2.3534824e+13
A44: Cameroon | B44: =VLOOKUP(A44,GDP_LCU!A:B,2,FALSE) -> CMR | C44: 16885901000000
A45: Congo, Dem. Rep. | B45: =VLOOKUP(A45,GDP_LCU!A:B,2,FALSE) -> COD | C45: 64818397251000
A46: Congo, Rep. | B46: =VLOOKUP(A46,GDP_LCU!A:B,2,FALSE) -> COG | C46: 3278668347200
A47: Colombia | B47: =VLOOKUP(A47,GDP_LCU!A:B,2,FALSE) -> COL | C47: 727934000000001
A48: Comoros | B48: =VLOOKUP(A48,GDP_LCU!A:B,2,FALSE) -> COM | C48: 493087000000
A49: Cabo Verde | B49: =VLOOKUP(A49,GDP_LCU!A:B,2,FALSE) -> CPV | C49: 1.485057e+11
A50: Costa Rica | B50: =VLOOKUP(A50,GDP_LCU!A:B,2,FALSE) -> CRI | C50: 24324029648000
...

Sheet G
A1: Country Name | B1: Country Code | C1: Gov_Cons_2020
A2: Aruba | B2: =VLOOKUP(A2,GDP_LCU!A:B,2,FALSE) -> ABW | C2: 1367570000
A3: Africa Eastern and Southern | B3: =VLOOKUP(A3,GDP_LCU!A:B,2,FALSE) -> AFE
A4: Afghanistan | B4: =VLOOKUP(A4,GDP_LCU!A:B,2,FALSE) -> AFG
A5: Africa Western and Central | B5: =VLOOKUP(A5,GDP_LCU!A:B,2,FALSE) -> AFW
A6: Angola | B6: =VLOOKUP(A6,GDP_LCU!A:B,2,FALSE) -> AGO | C6: 2608070000000
A7: Albania | B7: =VLOOKUP(A7,GDP_LCU!A:B,2,FALSE) -> ALB | C7: 191980010300
A8: Andorra | B8: =VLOOKUP(A8,GDP_LCU!A:B,2,FALSE) -> AND
A9: Arab World | B9: =VLOOKUP(A9,GDP_LCU!A:B,2,FALSE) -> ARB
A10: United Arab Emirates | B10: =VLOOKUP(A10,GDP_LCU!A:B,2,FALSE) -> ARE | C10: 188124684400
A11: Argentina | B11: =VLOOKUP(A11,GDP_LCU!A:B,2,FALSE) -> ARG | C11: 3544907053700
A12: Armenia | B12: =VLOOKUP(A12,GDP_LCU!A:B,2,FALSE) -> ARM | C12: 822139600000
A13: American Samoa | B13: =VLOOKUP(A13,GDP_LCU!A:B,2,FALSE) -> ASM
A14: Antigua and Barbuda | B14: =VLOOKUP(A14,GDP_LCU!A:B,2,FALSE) -> ATG
A15: Australia | B15: =VLOOKUP(A15,GDP_LCU!A:B,2,FALSE) -> AUS | C15: 396695000000
A16: Austria | B16: =VLOOKUP(A16,GDP_LCU!A:B,2,FALSE) -> AUT | C16: 77286760000
A17: Azerbaijan | B17: =VLOOKUP(A17,GDP_LCU!A:B,2,FALSE) -> AZE | C17: 9109700000
A18: Burundi | B18: =VLOOKUP(A18,GDP_LCU!A:B,2,FALSE) -> BDI | C18: 1514696512300
A19: Belgium | B19: =VLOOKUP(A19,GDP_LCU!A:B,2,FALSE) -> BEL | C19: 110290600000
A20: Benin | B20: =VLOOKUP(A20,GDP_LCU!A:B,2,FALSE) -> BEN | C20: 872068369700
A21: Burkina Faso | B21: =VLOOKUP(A21,GDP_LCU!A:B,2,FALSE) -> BFA | C21: 1925724000000
A22: Bangladesh | B22: =VLOOKUP(A22,GDP_LCU!A:B,2,FALSE) -> BGD | C22: 1841157000000
A23: Bulgaria | B23: =VLOOKUP(A23,GDP_LCU!A:B,2,FALSE) -> BGR | C23: 20111308000
A24: Bahrain | B24: =VLOOKUP(A24,GDP_LCU!A:B,2,FALSE) -> BHR | C24: 2280320000
A25: Bahamas, The | B25: =VLOOKUP(A25,GDP_LCU!A:B,2,FALSE) -> BHS | C25: 1636800000
A26: Bosnia and Herzegovina | B26: =VLOOKUP(A26,GDP_LCU!A:B,2,FALSE) -> BIH | C26: 6927584000
... A37: Canada | B37: =VLOOKUP(A37,GDP_LCU!A:B,2,FALSE) -> CAN | C37: 478063000000
A38: Central Europe and the Baltics | B38: =VLOOKUP(A38,GDP_LCU!A:B,2,FALSE) -> CEB
A39: Switzerland | B39: =VLOOKUP(A39,GDP_LCU!A:B,2,FALSE) -> CHE | C39: 81400874000
A40: Channel Islands | B40: =VLOOKUP(A40,GDP_LCU!A:B,2,FALSE) -> CHI
A41: Chile | B41: =VLOOKUP(A41,GDP_LCU!A:B,2,FALSE) -> CHL | C41: 29826322372000
A42: China, P.R.: Mainland | B42: =VLOOKUP(A42,GDP_LCU!A:B,2,FALSE) -> CHN | C42: 16544363964400
A43: Cote d'Ivoire | B43: =VLOOKUP(A43,GDP_LCU!A:B,2,FALSE) -> CIV | C43: 3830712000000
A44: Cameroon | B44: =VLOOKUP(A44,GDP_LCU!A:B,2,FALSE) -> CMR | C44: 2811635000000
A45: Congo, Dem. Rep. | B45: =VLOOKUP(A45,GDP_LCU!A:B,2,FALSE) -> COD | C45: 5911543000000
A46: Congo, Rep. | B46: =VLOOKUP(A46,GDP_LCU!A:B,2,FALSE) -> COG | C46: 1084304404300
A47: Colombia | B47: =VLOOKUP(A47,GDP_LCU!A:B,2,FALSE) -> COL | C47: 167207000000000
A48: Comoros | B48: =VLOOKUP(A48,GDP_LCU!A:B,2,FALSE) -> COM | C48: 53015000000
A49: Cabo Verde | B49: =VLOOKUP(A49,GDP_LCU!A:B,2,FALSE) -> CPV | C49: 43954153000
A50: Costa Rica | B50: =VLOOKUP(A50,GDP_LCU!A:B,2,FALSE) -> CRI | C50: 6337339445100
...

Sheet VAT Rates
A1: Country_Name | B1: Country_Code | C1: VAT Rate
A2: =VLOOKUP(B2,country_code!A:B,2,FALSE) -> Albania | B2: ALB | C2: 20
A3: =VLOOKUP(B3,country_code!A:B,2,FALSE) -> Argentina | B3: ARG | C3: 21
A4: =VLOOKUP(B4,country_code!A:B,2,FALSE) -> Armenia | B4: ARM | C4: 20
A5: Antigua and Barbuda | B5: ATG | C5: 15
A6: =VLOOKUP(B6,country_code!A:B,2,FALSE) -> Australia | B6: AUS | C6: 10
A7: =VLOOKUP(B7,country_code!A:B,2,FALSE) -> Austria | B7: AUT | C7: 20
A8: =VLOOKUP(B8,country_code!A:B,2,FALSE) -> Belgium | B8: BEL | C8: 21
A9: =VLOOKUP(B9,country_code!A:B,2,FALSE) -> Bangladesh | B9: BGD | C9: 15
A10: =VLOOKUP(B10,country_code!A:B,2,FALSE) -> Bulgaria | B10: BGR | C10: 20
A11: =VLOOKUP(B11,country_code!A:B,2,FALSE) -> Bahrain | B11: BHR | C11: 5
A12: =VLOOKUP(B12,country_code!A:B,2,FALSE) -> Bahamas, The | B12: BHS | C12: 12
A13: =VLOOKUP(B13,country_code!A:B,2,FALSE) -> Bosnia and Herzegovina | B13: BIH | C13: 17
A14: =VLOOKUP(B14,country_code!A:B,2,FALSE) -> Belarus | B14: BLR | C14: 20
A15: =VLOOKUP(B15,country_code!A:B,2,FALSE) -> Bolivia | B15: BOL | C15: 13
A16: =VLOOKUP(B16,country_code!A:B,2,FALSE) -> Brazil | B16: BRA | C16: 18
A17: =VLOOKUP(B17,country_code!A:B,2,FALSE) -> Barbados | B17: BRB | C17: 17.5
... A21: =VLOOKUP(B21,country_code!A:B,2,FALSE) -> Chile | B21: CHL | C21: 19
A22: China, P.R.: Mainland | B22: CHN | C22: 16
A23: =VLOOKUP(B23,country_code!A:B,2,FALSE) -> Costa Rica | B23: CRI | C23: 13
A24: =VLOOKUP(B24,country_code!A:B,2,FALSE) -> Cyprus | B24: CYP | C24: 19
A25: =VLOOKUP(B25,country_code!A:B,2,FALSE) -> Czech Republic | B25: CZE | C25: 21
A26: =VLOOKUP(B26,country_code!A:B,2,FALSE) -> Germany | B26: DEU | C26: 19
A27: =VLOOKUP(B27,country_code!A:B,2,FALSE) -> Denmark | B27: DNK | C27: 25
A28: =VLOOKUP(B28,country_code!A:B,2,FALSE) -> Dominican Republic | B28: DOM | C28: 18
A29: =VLOOKUP(B29,country_code!A:B,2,FALSE) -> Ecuador | B29: ECU | C29: 12
A30: =VLOOKUP(B30,country_code!A:B,2,FALSE) -> Egypt, Arab Rep. | B30: EGY | C30: 14
A31: =VLOOKUP(B31,country_code!A:B,2,FALSE) -> Spain | B31: ESP | C31: 21
A32: =VLOOKUP(B32,country_code!A:B,2,FALSE) -> Estonia | B32: EST | C32: 20
A33: =VLOOKUP(B33,country_code!A:B,2,FALSE) -> Finland | B33: FIN | C33: 24
A34: =VLOOKUP(B34,country_code!A:B,2,FALSE) -> Fiji | B34: FJI | C34: 9
... A55: =VLOOKUP(B55,country_code!A:B,2,FALSE) -> Cambodia | B55: KHM | C55: 10
A56: Korea, Republic of | B56: KOR | C56: 10
A57: =VLOOKUP(B57,country_code!A:B,2,FALSE) -> Lebanon | B57: LBN | C57: 11
A58: =VLOOKUP(B58,country_code!A:B,2,FALSE) -> St. Lucia | B58: LCA | C58: 12.5
A59: Liechtenstein | B59: LIE | C59: 7.7
A60: =VLOOKUP(B60,country_code!A:B,2,FALSE) -> Sri Lanka | B60: LKA | C60: 15
A61: =VLOOKUP(B61,country_code!A:B,2,FALSE) -> Lithuania | B61: LTU | C61: 21
A62: =VLOOKUP(B62,country_code!A:B,2,FALSE) -> Luxembourg | B62: LUX | C62: 17
A63: =VLOOKUP(B63,country_code!A:B,2,FALSE) -> Latvia | B63: LVA | C63: 21
...

Sheet country_code
A1: Country_Code | B1: Country_Name | C1: Country_Code | D1: Region_Code | E1: Region_Desc | F1: Income_Group | G1: Resource_Rich | H1: Oil_Gas_Rich | I1: Small_State | J1: Small_Island_State
A2: AFG | B2: Afghanistan | C2: AFG | D2: SA | E2: South Asia | F2: Low Income | G2: NO | H2: NO | I2: NO | J2: NO
A3: ALB | B3: Albania | C3: ALB | D3: ECA | E3: Eastern Europe & Central Asia | F3: Upper Middle Income | G3: NO | H3: NO | I3: NO | J3: NO
A4: DZA | B4: Algeria | C4: DZA | D4: MENA | E4: Middle East & North Africa | F4: Upper Middle Income | G4: YES | H4: YES | I4: NO | J4: NO
A5: ASM | B5: American Samoa | C5: ASM | D5: EAP | E5: East Asia & Pacific | F5: Upper Middle Income | G5: NO | H5: NO | I5: NO | J5: NO
A6: ADO | B6: Andorra | C6: ADO | D6: WER | E6: Western Europe | F6: High Income | G6: NO | H6: NO | I6: NO | J6: NO
A7: AGO | B7: Angola | C7: AGO | D7: SSA | E7: Sub-Saharan Africa | F7: Upper Middle Income | G7: YES | H7: YES | I7: NO | J7: NO
A8: AIA | B8: Anguilla | C8: AIA | D8: LAC | E8: Latin America & the Caribbean | F8: High Income | G8: NO | H8: NO | I8: YES | J8: YES
A9: ATG | B9: Antigua and Barbuda | C9: ATG | D9: LAC | E9: Latin America & the Caribbean | F9: High Income | G9: NO | H9: NO | I9: YES | J9: YES
A10: ARG | B10: Argentina | C10: ARG | D10: LAC | E10: Latin America & the Caribbean | F10: Upper Middle Income | G10: YES | H10: YES | I10: NO | J10: NO
A11: ARM | B11: Armenia | C11: ARM | D11: ECA | E11: Eastern Europe & Central Asia | F11: Lower Middle Income | G11: NO | H11: NO | I11: NO | J11: NO
A12: ABW | B12: Aruba | C12: ABW | D12: LAC | E12: Latin America & the Caribbean | F12: High Income | G12: NO | H12: NO | I12: NO | J12: NO
... A126: MUS | B126: Mauritius | C126: MUS | D126: SSA | E126: Sub-Saharan Africa | F126: Upper Middle Income | G126: NO | H126: NO | I126: YES | J126: YES
A127: MYT | B127: Mayotte | C127: MYT | D127: LAC | E127: Latin America & the Caribbean | G127: NO | H127: NO | I127: YES | J127: NO
A128: MEX | B128: Mexico | C128: MEX | D128: LAC | E128: Latin America & the Caribbean | F128: Upper Middle Income | G128: YES | H128: YES | I128: NO | J128: NO
A129: FSM | B129: Micronesia, Fed. Sts. | C129: FSM | D129: EAP | E129: East Asia & Pacific | F129: Lower Middle Income | G129: NO | H129: NO | I129: YES | J129: YES
A130: MDA | B130: Moldova | C130: MDA | D130: ECA | E130: Eastern Europe & Central Asia | F130: Lower Middle Income | G130: NO | H130: NO | I130: NO | J130: NO
A131: MCO | B131: Monaco | C131: MCO | D131: WER | E131: Western Europe | F131: High Income | G131: NO | H131: NO | I131: YES | J131: NO
A132: MNG | B132: Mongolia | C132: MNG | D132: EAP | E132: East Asia & Pacific | F132: Lower Middle Income | G132: YES | H132: NO | I132: NO | J132: NO
A133: MNE | B133: Montenegro | C133: MNE | D133: ECA | E133: Eastern Europe & Central Asia | F133: Upper Middle Income | G133: NO | H133: NO | I133: YES | J133: NO
A134: MAR | B134: Morocco | C134: MAR | D134: MENA | E134: Middle East & North Africa | F134: Lower Middle Income | G134: NO | H134: NO | I134: NO | J134: NO
A135: MOZ | B135: Mozambique | C135: MOZ | D135: SSA | E135: Sub-Saharan Africa | F135: Low Income | G135: NO | H135: NO | I135: NO | J135: NO
A136: MMR | B136: Myanmar | C136: MMR | D136: EAP | E136: East Asia & Pacific | F136: Lower Middle Income | G136: NO | H136: NO | I136: NO | J136: NO
A137: NAM | B137: Namibia | C137: NAM | D137: SSA | E137: Sub-Saharan Africa | F137: Upper Middle Income | G137: NO | H137: NO | I137: YES | J137: NO
A138: NRU | B138: Nauru | C138: NRU | D138: EAP | E138: East Asia & Pacific | F138: High Income | G138: NO | H138: NO | I138: YES | J138: NO
A139: NPL | B139: Nepal | C139: NPL | D139: SA | E139: South Asia | F139: Low Income | G139: NO | H139: NO | I139: NO | J139: NO
... A217: MSR | B217: Montserrat | C217: MSR | D217: LAC | E217: Latin America & the Caribbean | F217: High Income | G217: NO | H217: NO | I217: YES | J217: YES
